<?xml version="1.0"?>
<robot name="arm">
    <material name="blue0">
        <color rgba="0 0 1 1"/>
    </material>

    <material name="blue1">
        <color rgba="0 0 0.83 1"/>
    </material>

    <material name="blue2">
        <color rgba="0 0 0.67 1"/>
    </material>

    <material name="blue3">
        <color rgba="0 0 0.5 1"/>
    </material>

    <material name="blue4">
        <color rgba="0 0 0.33 1"/>
    </material>

    <material name="blue5">
        <color rgba="0 0 0.17 1"/>
    </material>

    <material name="white">
        <color rgba="1 1 1 1"/>
    </material>

    <material name="gray">
        <color rgba="0.5 0.5 0.5 1"/>
    </material>

    <material name="green">
        <color rgba="0 0.7 0 1"/>
    </material>

    <link name="base_link">
        <inertial>
            <mass value="0.001"/>
            <inertia ixx="0.5" ixy="0" ixz="0" iyy="0.5" iyz="0" izz="0.5"/>
        </inertial>
        <visual>
            <geometry>
                <box size="0.5 0.5 0.5"/>
            </geometry>
            <material name="gray"/>
        </visual>
    </link>

    <joint name="joint0" type="fixed">
        <parent link="base_link"/>
        <child link="motor0"/>
        <origin xyz="0.25 0 0.25" rpy="0 0 0"/>
    </joint>

    <link name="motor0">
        <inertial>
            <mass value="0.001"/>
            <inertia ixx="0.0020833333" ixy="0" ixz="0" iyy="0.0033333333" iyz="0" izz="0.0020833333"/>
        </inertial>
        <visual>
            <geometry>
                <box size="0.2 0.1 0.2"/>
            </geometry>
            <material name="blue0"/>
        </visual>
    </link>

    <joint name="joint1" type="revolute">
        <parent link="motor0"/>
        <child link="motor1"/>
        <origin xyz="0.15 0 0" rpy="0 0 -1.5707963268"/>
        <axis xyz="0 1 0"/>
        <limit effort="5000" velocity="1000"/>
    </joint>

    <link name="motor1">
        <inertial>
            <mass value="0.001"/>
            <inertia ixx="0.0020833333" ixy="0" ixz="0" iyy="0.0033333333" iyz="0" izz="0.0020833333"/>
        </inertial>
        <visual>
            <geometry>
                <box size="0.2 0.1 0.2"/>
            </geometry>
            <material name="blue1"/>
        </visual>
    </link>

    <joint name="joint2" type="revolute">
        <parent link="motor1"/>
        <child link="motor2"/>
        <origin xyz="0.15 0 0" rpy="0 0 1.5707963268"/>
        <axis xyz="0 1 0"/>
        <limit effort="1000" velocity="3000"/>
    </joint>

    <link name="motor2">
        <inertial>
            <mass value="0.001"/>
            <inertia ixx="0.0020833333" ixy="0" ixz="0" iyy="0.0033333333" iyz="0" izz="0.0020833333"/>
        </inertial>
        <visual>
            <geometry>
                <box size="0.2 0.1 0.2"/>
            </geometry>
            <material name="blue2"/>
        </visual>
    </link>

    <joint name="joint3" type="revolute">
        <parent link="motor2"/>
        <child link="segment1"/>
        <origin xyz="0.45 0 0" rpy="0 0 0"/>
        <axis xyz="1 0 0"/>
        <limit effort="1000" velocity="3000"/>
    </joint>

    <link name="segment1">
        <inertial>
            <mass value="0.001"/>
            <inertia ixx="0.00375" ixy="0" ixz="0" iyy="0.0227083333" iyz="0" izz="0.0227083333"/>
        </inertial>
        <visual>
            <geometry>
                <box size="0.7 0.15 0.15"/>
            </geometry>
            <material name="white"/>
        </visual>
    </link>

    <joint name="joint4" type="fixed">
        <parent link="segment1"/>
        <child link="motor3"/>
        <origin xyz="0.28 0 0" rpy="0 0 -1.5707963268"/>
    </joint>

    <link name="motor3">
        <inertial>
            <mass value="0.001"/>
            <inertia ixx="0.0020833333" ixy="0" ixz="0" iyy="0.0033333333" iyz="0" izz="0.0020833333"/>
        </inertial>
        <visual>
            <geometry>
                <box size="0.2 0.1 0.2"/>
            </geometry>
            <material name="blue3"/>
        </visual>
    </link>

    <joint name="joint5" type="revolute">
        <parent link="motor3"/>
        <child link="motor4"/>
        <origin xyz="0.15 0 0" rpy="0 0 1.5707963268"/>
        <axis xyz="0 1 0"/>
        <limit effort="1000" velocity="3000"/>
    </joint>

    <link name="motor4">
        <inertial>
            <mass value="0.001"/>
            <inertia ixx="0.0020833333" ixy="0" ixz="0" iyy="0.0033333333" iyz="0" izz="0.0020833333"/>
        </inertial>
        <visual>
            <geometry>
                <box size="0.2 0.1 0.2"/>
            </geometry>
            <material name="blue4"/>
        </visual>
    </link>

    <joint name="joint6" type="revolute">
        <parent link="motor4"/>
        <child link="segment2"/>
        <origin xyz="0.45 0 0" rpy="0 0 0"/>
        <axis xyz="1 0 0"/>
        <limit effort="1000" velocity="3000"/>
    </joint>

    <link name="segment2">
        <inertial>
            <mass value="0.001"/>
            <inertia ixx="0.00375" ixy="0" ixz="0" iyy="0.0227083333" iyz="0" izz="0.0227083333"/>
        </inertial>
        <visual>
            <geometry>
                <box size="0.7 0.15 0.15"/>
            </geometry>
            <material name="white"/>
        </visual>
    </link>

    <joint name="joint7" type="fixed">
        <parent link="segment2"/>
        <child link="motor5"/>
        <origin xyz="0.28 0 0" rpy="0 0 -1.5707963268"/>
    </joint>

    <link name="motor5">
        <inertial>
            <mass value="0.001"/>
            <inertia ixx="0.0020833333" ixy="0" ixz="0" iyy="0.0033333333" iyz="0" izz="0.0020833333"/>
        </inertial>
        <visual>
            <geometry>
                <box size="0.2 0.1 0.2"/>
            </geometry>
            <material name="blue5"/>
        </visual>
    </link>

    <joint name="joint8" type="revolute">
        <parent link="motor5"/>
        <child link="hand"/>
        <origin xyz="-0.15 0 0" rpy="0 0 1.5707963268"/>
        <axis xyz="0 1 0"/>
        <limit effort="1000" velocity="3000"/>
    </joint>

    <link name="hand">
        <inertial>
            <mass value="0.001"/>
            <inertia ixx="0.0008333333" ixy="0" ixz="0" iyy="0.0070833333" iyz="0" izz="0.0070833333"/>
        </inertial>
        <visual>
            <origin xyz="0.15 0 0" rpy="0 0 0"/>
            <geometry>
                <box size="0.4, 0.1, 0.1"/>
            </geometry>
            <material name="green"/>
        </visual>
    </link>
</robot>